[2019-08-27 20:28:42,437][app.py:1034][DEBUG]- AUC_ROC: 0.987857 ; AUC_PR: 0.957423 
[2019-08-27 20:30:51,055][app.py:1161][DEBUG]- AUC_ROC: 0.987968 ; AUC_PR: 0.957723 
[2019-08-27 20:36:08,897][app.py:1161][DEBUG]- AUC_ROC: 0.988110 ; AUC_PR: 0.958183 
[2019-08-27 20:36:56,180][app.py:1161][DEBUG]- AUC_ROC: 0.988110 ; AUC_PR: 0.958183 
[2019-08-27 20:37:33,541][app.py:1161][DEBUG]- AUC_ROC: 0.988151 ; AUC_PR: 0.958308 
[2019-08-27 20:37:51,150][app.py:1161][DEBUG]- AUC_ROC: 0.988151 ; AUC_PR: 0.958308 
[2019-08-27 20:38:14,791][app.py:1161][DEBUG]- AUC_ROC: 0.988154 ; AUC_PR: 0.958312 
[2019-08-27 20:40:49,774][app.py:1161][DEBUG]- AUC_ROC: 0.988218 ; AUC_PR: 0.958493 
[2019-08-27 20:41:07,907][app.py:1161][DEBUG]- AUC_ROC: 0.988218 ; AUC_PR: 0.958493 
[2019-08-27 21:23:08,472][app.py:1035][DEBUG]- AUC_ROC: 0.987857 ; AUC_PR: 0.957423 
[2019-08-27 21:28:12,918][app.py:1035][DEBUG]- AUC_ROC: 0.987857 ; AUC_PR: 0.957423 
[2019-08-27 21:29:01,695][app.py:1036][DEBUG]- AUC_ROC: 0.987857 ; AUC_PR: 0.957423 
[2019-08-27 21:29:50,993][app.py:1036][DEBUG]- AUC_ROC: 0.987857 ; AUC_PR: 0.957423 
[2019-08-27 21:30:41,466][app.py:1036][DEBUG]- AUC_ROC: 0.987857 ; AUC_PR: 0.957423 
[2019-08-27 21:34:06,973][app.py:1038][DEBUG]- AUC_ROC: 0.987857 ; AUC_PR: 0.957423 
[2019-08-27 21:34:47,938][app.py:1038][DEBUG]- AUC_ROC: 0.987857 ; AUC_PR: 0.957423 
[2019-08-27 21:35:37,168][app.py:1038][DEBUG]- AUC_ROC: 0.987857 ; AUC_PR: 0.957423 
[2019-08-27 21:39:17,168][app.py:1038][DEBUG]- AUC_ROC: 0.987857 ; AUC_PR: 0.957423 
[2019-08-27 21:43:19,110][app.py:1038][DEBUG]- AUC_ROC: 0.987857 ; AUC_PR: 0.957423 
[2019-08-27 21:44:21,739][app.py:1038][DEBUG]- AUC_ROC: 0.987857 ; AUC_PR: 0.957423 
[2019-08-27 21:45:09,333][app.py:1038][DEBUG]- AUC_ROC: 0.987857 ; AUC_PR: 0.957423 
[2019-08-27 21:45:39,942][app.py:1038][DEBUG]- AUC_ROC: 0.987857 ; AUC_PR: 0.957423 
[2019-08-27 21:46:30,918][app.py:1038][DEBUG]- AUC_ROC: 0.987857 ; AUC_PR: 0.957423 
[2019-08-28 12:04:56,815][app.py:1061][DEBUG]- AUC_ROC: 0.992262 ; AUC_PR: 0.971145 
[2019-08-28 12:10:19,516][app.py:1063][DEBUG]- AUC_ROC: 0.992127 ; AUC_PR: 0.968720 
[2019-08-28 12:10:48,238][app.py:1063][DEBUG]- AUC_ROC: 0.992178 ; AUC_PR: 0.970440 
[2019-08-28 12:12:06,728][app.py:1065][DEBUG]- AUC_ROC: 0.992548 ; AUC_PR: 0.970678 
[2019-08-28 12:13:17,329][app.py:1065][DEBUG]- AUC_ROC: 0.993001 ; AUC_PR: 0.971597 
[2019-08-28 12:15:16,473][app.py:1073][DEBUG]- AUC_ROC: 0.991651 ; AUC_PR: 0.969726 
[2019-08-28 12:15:46,768][app.py:1073][DEBUG]- AUC_ROC: 0.991106 ; AUC_PR: 0.969593 
[2019-08-28 12:17:20,830][app.py:1074][DEBUG]- AUC_ROC: 0.992667 ; AUC_PR: 0.971414 
[2019-08-28 12:20:16,998][app.py:1074][DEBUG]- AUC_ROC: 0.991261 ; AUC_PR: 0.968880 
[2019-08-28 12:21:03,160][app.py:1074][DEBUG]- AUC_ROC: 0.991136 ; AUC_PR: 0.968333 
[2019-08-28 12:23:12,244][app.py:1074][DEBUG]- AUC_ROC: 0.990819 ; AUC_PR: 0.969253 
[2019-08-28 12:25:01,474][app.py:1069][DEBUG]- AUC_ROC: 0.992938 ; AUC_PR: 0.970890 
[2019-08-28 12:29:10,200][app.py:1068][DEBUG]- AUC_ROC: 0.992740 ; AUC_PR: 0.971522 
[2019-08-28 12:30:15,774][app.py:1068][DEBUG]- AUC_ROC: 0.992175 ; AUC_PR: 0.970908 
[2019-08-28 12:32:45,513][app.py:1068][DEBUG]- AUC_ROC: 0.991337 ; AUC_PR: 0.968977 
[2019-08-28 12:33:23,007][app.py:1068][DEBUG]- AUC_ROC: 0.992548 ; AUC_PR: 0.971517 
[2019-08-28 12:34:34,015][app.py:1068][DEBUG]- AUC_ROC: 0.992826 ; AUC_PR: 0.970792 
[2019-08-28 12:35:10,340][app.py:1068][DEBUG]- AUC_ROC: 0.990921 ; AUC_PR: 0.968814 
[2019-08-28 12:39:17,677][app.py:1072][DEBUG]- AUC_ROC: 0.992380 ; AUC_PR: 0.968885 
[2019-08-28 13:31:16,981][app.py:1039][DEBUG]- AUC_ROC: 0.992175 ; AUC_PR: 0.970833 
[2019-08-28 13:31:18,997][app.py:1166][DEBUG]- AUC_ROC: 0.992175 ; AUC_PR: 0.970833 
[2019-08-28 13:31:24,389][app.py:1166][DEBUG]- AUC_ROC: 0.992175 ; AUC_PR: 0.970833 
[2019-08-28 13:31:27,994][app.py:1166][DEBUG]- AUC_ROC: 0.992175 ; AUC_PR: 0.970833 
[2019-08-28 13:31:33,296][app.py:1166][DEBUG]- AUC_ROC: 0.992175 ; AUC_PR: 0.970833 
[2019-08-28 13:31:35,158][app.py:1166][DEBUG]- AUC_ROC: 0.992175 ; AUC_PR: 0.970833 
[2019-08-28 13:32:55,065][app.py:1039][DEBUG]- AUC_ROC: 0.992330 ; AUC_PR: 0.970508 
[2019-08-28 13:33:08,684][app.py:1039][DEBUG]- AUC_ROC: 0.992330 ; AUC_PR: 0.970508 
[2019-08-28 13:33:15,484][app.py:1039][DEBUG]- AUC_ROC: 0.992330 ; AUC_PR: 0.970508 
[2019-08-28 13:33:25,705][app.py:1166][DEBUG]- AUC_ROC: 0.992330 ; AUC_PR: 0.970508 
[2019-08-28 13:33:28,147][app.py:1166][DEBUG]- AUC_ROC: 0.992330 ; AUC_PR: 0.970508 
[2019-08-28 13:33:29,486][app.py:1166][DEBUG]- AUC_ROC: 0.992330 ; AUC_PR: 0.970508 
[2019-08-28 13:35:02,120][app.py:1039][DEBUG]- AUC_ROC: 0.990090 ; AUC_PR: 0.967299 
[2019-08-28 13:35:05,569][app.py:1167][DEBUG]- AUC_ROC: 0.990090 ; AUC_PR: 0.967299 
[2019-08-28 13:35:07,425][app.py:1167][DEBUG]- AUC_ROC: 0.990090 ; AUC_PR: 0.967299 
[2019-08-28 13:35:09,876][app.py:1167][DEBUG]- AUC_ROC: 0.990090 ; AUC_PR: 0.967299 
[2019-08-28 13:35:12,386][app.py:1167][DEBUG]- AUC_ROC: 0.990090 ; AUC_PR: 0.967299 
[2019-08-28 13:36:24,334][app.py:1167][DEBUG]- AUC_ROC: 0.990090 ; AUC_PR: 0.967299 
[2019-08-28 13:41:08,910][app.py:1039][DEBUG]- AUC_ROC: 0.992260 ; AUC_PR: 0.970585 
[2019-08-28 13:41:16,995][app.py:1039][DEBUG]- AUC_ROC: 0.992260 ; AUC_PR: 0.970585 
[2019-08-28 13:43:05,499][app.py:1039][DEBUG]- AUC_ROC: 0.991912 ; AUC_PR: 0.968733 
[2019-08-28 13:44:49,011][app.py:1039][DEBUG]- AUC_ROC: 0.992335 ; AUC_PR: 0.972012 
[2019-08-28 13:45:59,041][app.py:1039][DEBUG]- AUC_ROC: 0.991301 ; AUC_PR: 0.969361 
[2019-08-28 13:52:11,510][app_newest.py:1004][DEBUG]- AUC_ROC: 0.992602 ; AUC_PR: 0.970285 
[2019-08-28 13:52:56,887][app_newest.py:1004][DEBUG]- AUC_ROC: 0.992487 ; AUC_PR: 0.970580 
[2019-08-28 13:53:31,495][app_newest.py:1004][DEBUG]- AUC_ROC: 0.993322 ; AUC_PR: 0.971846 
[2019-08-28 13:56:22,302][app_newest.py:1008][DEBUG]- AUC_ROC: 0.993322 ; AUC_PR: 0.971846 
[2019-08-28 13:56:23,803][app.py:1761][ERROR]- Exception on /frombar [POST]
Traceback (most recent call last):
  File "C:\Users\fx\PycharmProjects\webservice\venv\lib\site-packages\flask\app.py", line 2292, in wsgi_app
    response = self.full_dispatch_request()
  File "C:\Users\fx\PycharmProjects\webservice\venv\lib\site-packages\flask\app.py", line 1815, in full_dispatch_request
    rv = self.handle_user_exception(e)
  File "C:\Users\fx\PycharmProjects\webservice\venv\lib\site-packages\flask\app.py", line 1718, in handle_user_exception
    reraise(exc_type, exc_value, tb)
  File "C:\Users\fx\PycharmProjects\webservice\venv\lib\site-packages\flask\_compat.py", line 35, in reraise
    raise value
  File "C:\Users\fx\PycharmProjects\webservice\venv\lib\site-packages\flask\app.py", line 1813, in full_dispatch_request
    rv = self.dispatch_request()
  File "C:\Users\fx\PycharmProjects\webservice\venv\lib\site-packages\flask\app.py", line 1799, in dispatch_request
    return self.view_functions[rule.endpoint](**req.view_args)
  File "C:\Users\fx\PycharmProjects\new\app_newest.py", line 1118, in frombar
    bar = create_bar_plot_highlight(relations, bar_index, bar_value, relation)
  File "C:\Users\fx\PycharmProjects\new\app_newest.py", line 785, in create_bar_plot_highlight
    colors[relation] = 'crimson'
IndexError: list assignment index out of range
[2019-08-28 13:56:25,341][app.py:1761][ERROR]- Exception on /frombar [POST]
Traceback (most recent call last):
  File "C:\Users\fx\PycharmProjects\webservice\venv\lib\site-packages\flask\app.py", line 2292, in wsgi_app
    response = self.full_dispatch_request()
  File "C:\Users\fx\PycharmProjects\webservice\venv\lib\site-packages\flask\app.py", line 1815, in full_dispatch_request
    rv = self.handle_user_exception(e)
  File "C:\Users\fx\PycharmProjects\webservice\venv\lib\site-packages\flask\app.py", line 1718, in handle_user_exception
    reraise(exc_type, exc_value, tb)
  File "C:\Users\fx\PycharmProjects\webservice\venv\lib\site-packages\flask\_compat.py", line 35, in reraise
    raise value
  File "C:\Users\fx\PycharmProjects\webservice\venv\lib\site-packages\flask\app.py", line 1813, in full_dispatch_request
    rv = self.dispatch_request()
  File "C:\Users\fx\PycharmProjects\webservice\venv\lib\site-packages\flask\app.py", line 1799, in dispatch_request
    return self.view_functions[rule.endpoint](**req.view_args)
  File "C:\Users\fx\PycharmProjects\new\app_newest.py", line 1118, in frombar
    bar = create_bar_plot_highlight(relations, bar_index, bar_value, relation)
  File "C:\Users\fx\PycharmProjects\new\app_newest.py", line 785, in create_bar_plot_highlight
    colors[relation] = 'crimson'
IndexError: list assignment index out of range
[2019-08-28 13:56:28,298][app.py:1761][ERROR]- Exception on /frombar [POST]
Traceback (most recent call last):
  File "C:\Users\fx\PycharmProjects\webservice\venv\lib\site-packages\flask\app.py", line 2292, in wsgi_app
    response = self.full_dispatch_request()
  File "C:\Users\fx\PycharmProjects\webservice\venv\lib\site-packages\flask\app.py", line 1815, in full_dispatch_request
    rv = self.handle_user_exception(e)
  File "C:\Users\fx\PycharmProjects\webservice\venv\lib\site-packages\flask\app.py", line 1718, in handle_user_exception
    reraise(exc_type, exc_value, tb)
  File "C:\Users\fx\PycharmProjects\webservice\venv\lib\site-packages\flask\_compat.py", line 35, in reraise
    raise value
  File "C:\Users\fx\PycharmProjects\webservice\venv\lib\site-packages\flask\app.py", line 1813, in full_dispatch_request
    rv = self.dispatch_request()
  File "C:\Users\fx\PycharmProjects\webservice\venv\lib\site-packages\flask\app.py", line 1799, in dispatch_request
    return self.view_functions[rule.endpoint](**req.view_args)
  File "C:\Users\fx\PycharmProjects\new\app_newest.py", line 1118, in frombar
    bar = create_bar_plot_highlight(relations, bar_index, bar_value, relation)
  File "C:\Users\fx\PycharmProjects\new\app_newest.py", line 785, in create_bar_plot_highlight
    colors[relation] = 'crimson'
IndexError: list assignment index out of range
[2019-08-28 14:02:00,094][app_newest.py:1135][DEBUG]- AUC_ROC: 0.993322 ; AUC_PR: 0.971846 
[2019-08-28 14:02:00,096][app_newest.py:1135][DEBUG]- AUC_ROC: 0.993322 ; AUC_PR: 0.971846 
[2019-08-28 14:04:15,052][app_newest.py:1007][DEBUG]- AUC_ROC: 0.993322 ; AUC_PR: 0.971846 
[2019-08-28 14:06:18,128][app_newest.py:1135][DEBUG]- AUC_ROC: 0.993215 ; AUC_PR: 0.970263 
[2019-08-28 14:06:29,380][app_newest.py:1135][DEBUG]- AUC_ROC: 0.993215 ; AUC_PR: 0.970263 
[2019-08-28 14:06:30,528][app_newest.py:1135][DEBUG]- AUC_ROC: 0.993215 ; AUC_PR: 0.970263 
[2019-08-28 14:06:40,356][app_newest.py:1135][DEBUG]- AUC_ROC: 0.993215 ; AUC_PR: 0.970263 
[2019-08-28 14:12:51,151][app_newest.py:1135][DEBUG]- AUC_ROC: 0.992902 ; AUC_PR: 0.969952 
[2019-08-28 14:31:56,139][app_newest.py:1007][DEBUG]- AUC_ROC: 0.993322 ; AUC_PR: 0.971846 
[2019-08-30 09:37:04,865][app_newest.py:1007][DEBUG]- AUC_ROC: 0.993322 ; AUC_PR: 0.971846 
[2019-08-30 09:38:41,537][app_newest.py:1007][DEBUG]- AUC_ROC: 0.993322 ; AUC_PR: 0.971846 
[2019-08-30 09:46:06,342][app.py:1761][ERROR]- Exception on /cluster [POST]
Traceback (most recent call last):
  File "C:\Users\fx\PycharmProjects\webservice\venv\lib\site-packages\flask\app.py", line 2292, in wsgi_app
    response = self.full_dispatch_request()
  File "C:\Users\fx\PycharmProjects\webservice\venv\lib\site-packages\flask\app.py", line 1815, in full_dispatch_request
    rv = self.handle_user_exception(e)
  File "C:\Users\fx\PycharmProjects\webservice\venv\lib\site-packages\flask\app.py", line 1718, in handle_user_exception
    reraise(exc_type, exc_value, tb)
  File "C:\Users\fx\PycharmProjects\webservice\venv\lib\site-packages\flask\_compat.py", line 35, in reraise
    raise value
  File "C:\Users\fx\PycharmProjects\webservice\venv\lib\site-packages\flask\app.py", line 1813, in full_dispatch_request
    rv = self.dispatch_request()
  File "C:\Users\fx\PycharmProjects\webservice\venv\lib\site-packages\flask\app.py", line 1799, in dispatch_request
    return self.view_functions[rule.endpoint](**req.view_args)
  File "C:\Users\fx\PycharmProjects\new\app_umls.py", line 925, in cluster
    matrix, bar_index, bar_value, entities, relations, GROUND_TRUTH, distribution_1, last, re_ground_truth, entity_embedding = initiate_data()
  File "C:\Users\fx\PycharmProjects\new\app_umls.py", line 164, in initiate_data
    with open(relation_datafile, 'r') as f:
FileNotFoundError: [Errno 2] No such file or directory: 'D:/knowledge graph/rescal.py-master/data/uml_relation.txt'
[2019-08-30 09:46:50,396][app.py:1761][ERROR]- Exception on /cluster [POST]
Traceback (most recent call last):
  File "C:\Users\fx\PycharmProjects\webservice\venv\lib\site-packages\flask\app.py", line 2292, in wsgi_app
    response = self.full_dispatch_request()
  File "C:\Users\fx\PycharmProjects\webservice\venv\lib\site-packages\flask\app.py", line 1815, in full_dispatch_request
    rv = self.handle_user_exception(e)
  File "C:\Users\fx\PycharmProjects\webservice\venv\lib\site-packages\flask\app.py", line 1718, in handle_user_exception
    reraise(exc_type, exc_value, tb)
  File "C:\Users\fx\PycharmProjects\webservice\venv\lib\site-packages\flask\_compat.py", line 35, in reraise
    raise value
  File "C:\Users\fx\PycharmProjects\webservice\venv\lib\site-packages\flask\app.py", line 1813, in full_dispatch_request
    rv = self.dispatch_request()
  File "C:\Users\fx\PycharmProjects\webservice\venv\lib\site-packages\flask\app.py", line 1799, in dispatch_request
    return self.view_functions[rule.endpoint](**req.view_args)
  File "C:\Users\fx\PycharmProjects\new\app_umls.py", line 925, in cluster
    matrix, bar_index, bar_value, entities, relations, GROUND_TRUTH, distribution_1, last, re_ground_truth, entity_embedding = initiate_data()
  File "C:\Users\fx\PycharmProjects\new\app_umls.py", line 169, in initiate_data
    K = array(mat['R'], np.float32)
KeyError: 'R'
[2019-08-30 09:48:04,792][app.py:1761][ERROR]- Exception on /predict [POST]
Traceback (most recent call last):
  File "C:\Users\fx\PycharmProjects\webservice\venv\lib\site-packages\flask\app.py", line 2292, in wsgi_app
    response = self.full_dispatch_request()
  File "C:\Users\fx\PycharmProjects\webservice\venv\lib\site-packages\flask\app.py", line 1815, in full_dispatch_request
    rv = self.handle_user_exception(e)
  File "C:\Users\fx\PycharmProjects\webservice\venv\lib\site-packages\flask\app.py", line 1718, in handle_user_exception
    reraise(exc_type, exc_value, tb)
  File "C:\Users\fx\PycharmProjects\webservice\venv\lib\site-packages\flask\_compat.py", line 35, in reraise
    raise value
  File "C:\Users\fx\PycharmProjects\webservice\venv\lib\site-packages\flask\app.py", line 1813, in full_dispatch_request
    rv = self.dispatch_request()
  File "C:\Users\fx\PycharmProjects\webservice\venv\lib\site-packages\flask\app.py", line 1799, in dispatch_request
    return self.view_functions[rule.endpoint](**req.view_args)
  File "C:\Users\fx\PycharmProjects\new\app_umls.py", line 991, in predict
    matrix, bar_index, bar_value, entities, relations, GROUND_TRUTH, distribution_1, last, re_ground_truth, entity_embedding, matrix_ori = generate_data(cluster)
  File "C:\Users\fx\PycharmProjects\new\app_umls.py", line 290, in generate_data
    idx_test = np.load("idx_test_umls_rel.npy.npy")
  File "C:\Users\fx\PycharmProjects\webservice\venv\lib\site-packages\numpy\lib\npyio.py", line 415, in load
    fid = open(os_fspath(file), "rb")
FileNotFoundError: [Errno 2] No such file or directory: 'idx_test_umls_rel.npy.npy'
[2019-08-30 09:50:13,510][app.py:1761][ERROR]- Exception on /predict [POST]
Traceback (most recent call last):
  File "C:\Users\fx\PycharmProjects\webservice\venv\lib\site-packages\flask\app.py", line 2292, in wsgi_app
    response = self.full_dispatch_request()
  File "C:\Users\fx\PycharmProjects\webservice\venv\lib\site-packages\flask\app.py", line 1815, in full_dispatch_request
    rv = self.handle_user_exception(e)
  File "C:\Users\fx\PycharmProjects\webservice\venv\lib\site-packages\flask\app.py", line 1718, in handle_user_exception
    reraise(exc_type, exc_value, tb)
  File "C:\Users\fx\PycharmProjects\webservice\venv\lib\site-packages\flask\_compat.py", line 35, in reraise
    raise value
  File "C:\Users\fx\PycharmProjects\webservice\venv\lib\site-packages\flask\app.py", line 1813, in full_dispatch_request
    rv = self.dispatch_request()
  File "C:\Users\fx\PycharmProjects\webservice\venv\lib\site-packages\flask\app.py", line 1799, in dispatch_request
    return self.view_functions[rule.endpoint](**req.view_args)
  File "C:\Users\fx\PycharmProjects\new\app_umls.py", line 1005, in predict
    IDX = np.load("idx_umls_rel.npy.npy")
  File "C:\Users\fx\PycharmProjects\webservice\venv\lib\site-packages\numpy\lib\npyio.py", line 415, in load
    fid = open(os_fspath(file), "rb")
FileNotFoundError: [Errno 2] No such file or directory: 'idx_umls_rel.npy.npy'
[2019-08-30 09:52:02,962][app_umls.py:1007][DEBUG]- AUC_ROC: 0.984368 ; AUC_PR: 0.814418 
[2019-08-30 09:52:14,892][app_umls.py:1135][DEBUG]- AUC_ROC: 0.984368 ; AUC_PR: 0.814418 
[2019-08-30 09:52:19,968][app_umls.py:1135][DEBUG]- AUC_ROC: 0.984368 ; AUC_PR: 0.814418 
[2019-08-30 09:58:49,227][app_umls_no_innercluster.py:1034][DEBUG]- AUC_ROC: 0.984368 ; AUC_PR: 0.814418 
[2019-08-30 09:59:14,460][app_umls_no_innercluster.py:1162][DEBUG]- AUC_ROC: 0.984368 ; AUC_PR: 0.814418 
[2019-08-30 10:00:18,065][app_umls_no_innercluster.py:1162][DEBUG]- AUC_ROC: 0.984368 ; AUC_PR: 0.814418 
[2019-08-30 10:00:29,085][app_umls_no_innercluster.py:1162][DEBUG]- AUC_ROC: 0.984368 ; AUC_PR: 0.814418 
[2019-08-30 10:01:58,070][app_umls_no_innercluster.py:1034][DEBUG]- AUC_ROC: 0.984368 ; AUC_PR: 0.814418 
[2019-08-30 10:02:05,020][app_umls_no_innercluster.py:1162][DEBUG]- AUC_ROC: 0.984368 ; AUC_PR: 0.814418 
[2019-08-30 10:03:59,751][app_umls.py:1007][DEBUG]- AUC_ROC: 0.984368 ; AUC_PR: 0.814418 
[2019-08-30 10:04:06,594][app_umls.py:1135][DEBUG]- AUC_ROC: 0.984368 ; AUC_PR: 0.814418 
[2019-08-30 10:04:10,336][app_umls.py:1135][DEBUG]- AUC_ROC: 0.984368 ; AUC_PR: 0.814418 
[2019-08-30 10:10:31,164][app_umls.py:1007][DEBUG]- AUC_ROC: 0.984368 ; AUC_PR: 0.814418 
[2019-08-30 10:10:40,859][app_umls.py:1135][DEBUG]- AUC_ROC: 0.984368 ; AUC_PR: 0.814418 
[2019-08-30 10:12:35,227][app_umls.py:1007][DEBUG]- AUC_ROC: 0.984368 ; AUC_PR: 0.814418 
[2019-08-30 10:12:40,464][app_umls.py:1135][DEBUG]- AUC_ROC: 0.984368 ; AUC_PR: 0.814418 
[2019-08-30 10:19:42,631][app_umls_no_innercluster.py:1034][DEBUG]- AUC_ROC: 0.984368 ; AUC_PR: 0.814418 
[2019-08-30 10:19:48,453][app_umls_no_innercluster.py:1162][DEBUG]- AUC_ROC: 0.984368 ; AUC_PR: 0.814418 
[2019-08-30 10:22:16,424][app_umls_no_innercluster.py:1034][DEBUG]- AUC_ROC: 0.984368 ; AUC_PR: 0.814418 
[2019-08-30 10:22:23,522][app_umls_no_innercluster.py:1162][DEBUG]- AUC_ROC: 0.984368 ; AUC_PR: 0.814418 
[2019-08-30 10:35:14,292][app_umls_no_innercluster.py:1037][DEBUG]- AUC_ROC: 0.984368 ; AUC_PR: 0.814418 
[2019-08-30 10:35:14,400][app.py:1761][ERROR]- Exception on /predict [POST]
Traceback (most recent call last):
  File "C:\Users\fx\PycharmProjects\webservice\venv\lib\site-packages\flask\app.py", line 2292, in wsgi_app
    response = self.full_dispatch_request()
  File "C:\Users\fx\PycharmProjects\webservice\venv\lib\site-packages\flask\app.py", line 1815, in full_dispatch_request
    rv = self.handle_user_exception(e)
  File "C:\Users\fx\PycharmProjects\webservice\venv\lib\site-packages\flask\app.py", line 1718, in handle_user_exception
    reraise(exc_type, exc_value, tb)
  File "C:\Users\fx\PycharmProjects\webservice\venv\lib\site-packages\flask\_compat.py", line 35, in reraise
    raise value
  File "C:\Users\fx\PycharmProjects\webservice\venv\lib\site-packages\flask\app.py", line 1813, in full_dispatch_request
    rv = self.dispatch_request()
  File "C:\Users\fx\PycharmProjects\webservice\venv\lib\site-packages\flask\app.py", line 1799, in dispatch_request
    return self.view_functions[rule.endpoint](**req.view_args)
  File "C:\Users\fx\PycharmProjects\new\app_umls_no_innercluster.py", line 1040, in predict
    heatmap = create_plot( matrix, entities, relation, distribution_1[relation], entityX, entityY, last,operation[relation_chosen[-1]]["mX"], operation[relation_chosen[-1]]["mY"], operation[relation_chosen[-1]]["qX"], operation[relation_chosen[-1]]["qY"])
  File "C:\Users\fx\PycharmProjects\new\app_umls_no_innercluster.py", line 362, in create_plot
    test[j,:] = temp[dendro_leaves,:]
UnboundLocalError: local variable 'temp' referenced before assignment
[2019-08-30 11:04:30,275][app_umls_no_innercluster.py:1037][DEBUG]- AUC_ROC: 0.984368 ; AUC_PR: 0.814418 
[2019-08-30 11:04:30,345][app.py:1761][ERROR]- Exception on /predict [POST]
Traceback (most recent call last):
  File "C:\Users\fx\PycharmProjects\webservice\venv\lib\site-packages\flask\app.py", line 2292, in wsgi_app
    response = self.full_dispatch_request()
  File "C:\Users\fx\PycharmProjects\webservice\venv\lib\site-packages\flask\app.py", line 1815, in full_dispatch_request
    rv = self.handle_user_exception(e)
  File "C:\Users\fx\PycharmProjects\webservice\venv\lib\site-packages\flask\app.py", line 1718, in handle_user_exception
    reraise(exc_type, exc_value, tb)
  File "C:\Users\fx\PycharmProjects\webservice\venv\lib\site-packages\flask\_compat.py", line 35, in reraise
    raise value
  File "C:\Users\fx\PycharmProjects\webservice\venv\lib\site-packages\flask\app.py", line 1813, in full_dispatch_request
    rv = self.dispatch_request()
  File "C:\Users\fx\PycharmProjects\webservice\venv\lib\site-packages\flask\app.py", line 1799, in dispatch_request
    return self.view_functions[rule.endpoint](**req.view_args)
  File "C:\Users\fx\PycharmProjects\new\app_umls_no_innercluster.py", line 1040, in predict
    heatmap = create_plot( matrix, entities, relation, distribution_1[relation], entityX, entityY, last,operation[relation_chosen[-1]]["mX"], operation[relation_chosen[-1]]["mY"], operation[relation_chosen[-1]]["qX"], operation[relation_chosen[-1]]["qY"])
  File "C:\Users\fx\PycharmProjects\new\app_umls_no_innercluster.py", line 362, in create_plot
    test[j,:] = temp_1[dendro_leaves,:]
ValueError: could not broadcast input array from shape (11,135) into shape (135)
[2019-08-30 11:06:20,718][app_umls_no_innercluster.py:1037][DEBUG]- AUC_ROC: 0.984368 ; AUC_PR: 0.814418 
[2019-08-30 11:06:21,595][app.py:1761][ERROR]- Exception on /predict [POST]
Traceback (most recent call last):
  File "C:\Users\fx\PycharmProjects\webservice\venv\lib\site-packages\flask\app.py", line 2292, in wsgi_app
    response = self.full_dispatch_request()
  File "C:\Users\fx\PycharmProjects\webservice\venv\lib\site-packages\flask\app.py", line 1815, in full_dispatch_request
    rv = self.handle_user_exception(e)
  File "C:\Users\fx\PycharmProjects\webservice\venv\lib\site-packages\flask\app.py", line 1718, in handle_user_exception
    reraise(exc_type, exc_value, tb)
  File "C:\Users\fx\PycharmProjects\webservice\venv\lib\site-packages\flask\_compat.py", line 35, in reraise
    raise value
  File "C:\Users\fx\PycharmProjects\webservice\venv\lib\site-packages\flask\app.py", line 1813, in full_dispatch_request
    rv = self.dispatch_request()
  File "C:\Users\fx\PycharmProjects\webservice\venv\lib\site-packages\flask\app.py", line 1799, in dispatch_request
    return self.view_functions[rule.endpoint](**req.view_args)
  File "C:\Users\fx\PycharmProjects\new\app_umls_no_innercluster.py", line 1040, in predict
    heatmap = create_plot( matrix, entities, relation, distribution_1[relation], entityX, entityY, last,operation[relation_chosen[-1]]["mX"], operation[relation_chosen[-1]]["mY"], operation[relation_chosen[-1]]["qX"], operation[relation_chosen[-1]]["qY"])
  File "C:\Users\fx\PycharmProjects\new\app_umls_no_innercluster.py", line 355, in create_plot
    dendro = ff.create_dendrogram(temp_1, orientation='bottom')
  File "C:\Users\fx\PycharmProjects\webservice\venv\lib\site-packages\plotly\figure_factory\_dendrogram.py", line 91, in create_dendrogram
    hovertext=hovertext, color_threshold=color_threshold)
  File "C:\Users\fx\PycharmProjects\webservice\venv\lib\site-packages\plotly\figure_factory\_dendrogram.py", line 132, in __init__
    color_threshold)
  File "C:\Users\fx\PycharmProjects\webservice\venv\lib\site-packages\plotly\figure_factory\_dendrogram.py", line 276, in get_dendrogram_traces
    Z = linkagefun(d)
  File "C:\Users\fx\PycharmProjects\webservice\venv\lib\site-packages\plotly\figure_factory\_dendrogram.py", line 19, in <lambda>
    linkagefun=lambda x: sch.linkage(x, 'complete'),
  File "C:\Users\fx\PycharmProjects\webservice\venv\lib\site-packages\scipy\cluster\hierarchy.py", line 1064, in linkage
    n = int(distance.num_obs_y(y))
  File "C:\Users\fx\PycharmProjects\webservice\venv\lib\site-packages\scipy\spatial\distance.py", line 2403, in num_obs_y
    raise ValueError("The number of observations cannot be determined on "
ValueError: The number of observations cannot be determined on an empty distance matrix.
[2019-08-30 11:08:47,202][app_umls_no_innercluster.py:1038][DEBUG]- AUC_ROC: 0.984368 ; AUC_PR: 0.814418 
[2019-08-30 11:08:53,919][app_umls_no_innercluster.py:1166][DEBUG]- AUC_ROC: 0.984368 ; AUC_PR: 0.814418 
[2019-08-30 11:15:23,910][app_umls_no_innercluster.py:1045][DEBUG]- AUC_ROC: 0.984368 ; AUC_PR: 0.814418 
[2019-08-30 11:19:10,259][app_umls_no_innercluster.py:1173][DEBUG]- AUC_ROC: 0.984368 ; AUC_PR: 0.814418 
[2019-08-30 11:20:47,665][app_umls_no_innercluster.py:1173][DEBUG]- AUC_ROC: 0.984368 ; AUC_PR: 0.814418 
[2019-08-30 11:21:52,370][app_umls_no_innercluster.py:1045][DEBUG]- AUC_ROC: 0.984368 ; AUC_PR: 0.814418 
[2019-08-30 11:21:57,595][app_umls_no_innercluster.py:1173][DEBUG]- AUC_ROC: 0.984368 ; AUC_PR: 0.814418 
[2019-08-30 11:28:01,247][app_umls_no_innercluster.py:1047][DEBUG]- AUC_ROC: 0.984368 ; AUC_PR: 0.814418 
[2019-08-30 11:28:09,138][app_umls_no_innercluster.py:1175][DEBUG]- AUC_ROC: 0.984368 ; AUC_PR: 0.814418 
[2019-08-31 15:21:15,642][app_umls_no_innercluster.py:1047][DEBUG]- AUC_ROC: 0.984368 ; AUC_PR: 0.814418 
[2019-08-31 15:21:32,801][app_umls_no_innercluster.py:1175][DEBUG]- AUC_ROC: 0.984368 ; AUC_PR: 0.814418 
[2019-09-02 14:01:03,593][app_umls_no_innercluster.py:1047][DEBUG]- AUC_ROC: 0.984368 ; AUC_PR: 0.814418 
[2019-09-02 14:01:04,738][app.py:1761][ERROR]- Exception on /predict [POST]
Traceback (most recent call last):
  File "C:\Users\fx\PycharmProjects\webservice\venv\lib\site-packages\flask\app.py", line 2292, in wsgi_app
    response = self.full_dispatch_request()
  File "C:\Users\fx\PycharmProjects\webservice\venv\lib\site-packages\flask\app.py", line 1815, in full_dispatch_request
    rv = self.handle_user_exception(e)
  File "C:\Users\fx\PycharmProjects\webservice\venv\lib\site-packages\flask\app.py", line 1718, in handle_user_exception
    reraise(exc_type, exc_value, tb)
  File "C:\Users\fx\PycharmProjects\webservice\venv\lib\site-packages\flask\_compat.py", line 35, in reraise
    raise value
  File "C:\Users\fx\PycharmProjects\webservice\venv\lib\site-packages\flask\app.py", line 1813, in full_dispatch_request
    rv = self.dispatch_request()
  File "C:\Users\fx\PycharmProjects\webservice\venv\lib\site-packages\flask\app.py", line 1799, in dispatch_request
    return self.view_functions[rule.endpoint](**req.view_args)
  File "C:\Users\fx\PycharmProjects\new\app_umls_no_innercluster.py", line 1050, in predict
    heatmap = create_plot( matrix, entities, relation, distribution_1[relation], entityX, entityY, last,operation[relation_chosen[-1]]["mX"], operation[relation_chosen[-1]]["mY"], operation[relation_chosen[-1]]["qX"], operation[relation_chosen[-1]]["qY"])
  File "C:\Users\fx\PycharmProjects\new\app_umls_no_innercluster.py", line 356, in create_plot
    dendro = ff.create_dendrogram(temp_1, orientation='bottom')
  File "C:\Users\fx\PycharmProjects\webservice\venv\lib\site-packages\plotly\figure_factory\_dendrogram.py", line 91, in create_dendrogram
    hovertext=hovertext, color_threshold=color_threshold)
  File "C:\Users\fx\PycharmProjects\webservice\venv\lib\site-packages\plotly\figure_factory\_dendrogram.py", line 132, in __init__
    color_threshold)
  File "C:\Users\fx\PycharmProjects\webservice\venv\lib\site-packages\plotly\figure_factory\_dendrogram.py", line 276, in get_dendrogram_traces
    Z = linkagefun(d)
  File "C:\Users\fx\PycharmProjects\webservice\venv\lib\site-packages\plotly\figure_factory\_dendrogram.py", line 19, in <lambda>
    linkagefun=lambda x: sch.linkage(x, 'complete'),
  File "C:\Users\fx\PycharmProjects\webservice\venv\lib\site-packages\scipy\cluster\hierarchy.py", line 1064, in linkage
    n = int(distance.num_obs_y(y))
  File "C:\Users\fx\PycharmProjects\webservice\venv\lib\site-packages\scipy\spatial\distance.py", line 2403, in num_obs_y
    raise ValueError("The number of observations cannot be determined on "
ValueError: The number of observations cannot be determined on an empty distance matrix.
[2019-09-02 14:02:39,631][app_umls_no_innercluster.py:1047][DEBUG]- AUC_ROC: 0.984368 ; AUC_PR: 0.814418 
[2019-09-02 14:03:12,189][app_newest.py:1007][DEBUG]- AUC_ROC: 0.993322 ; AUC_PR: 0.971846 
[2019-09-02 14:05:06,365][app_newest.py:1068][DEBUG]- AUC_ROC: 0.993322 ; AUC_PR: 0.971846 
[2019-09-02 14:05:06,450][app.py:1761][ERROR]- Exception on /predict [POST]
Traceback (most recent call last):
  File "C:\Users\fx\PycharmProjects\webservice\venv\lib\site-packages\flask\app.py", line 2292, in wsgi_app
    response = self.full_dispatch_request()
  File "C:\Users\fx\PycharmProjects\webservice\venv\lib\site-packages\flask\app.py", line 1815, in full_dispatch_request
    rv = self.handle_user_exception(e)
  File "C:\Users\fx\PycharmProjects\webservice\venv\lib\site-packages\flask\app.py", line 1718, in handle_user_exception
    reraise(exc_type, exc_value, tb)
  File "C:\Users\fx\PycharmProjects\webservice\venv\lib\site-packages\flask\_compat.py", line 35, in reraise
    raise value
  File "C:\Users\fx\PycharmProjects\webservice\venv\lib\site-packages\flask\app.py", line 1813, in full_dispatch_request
    rv = self.dispatch_request()
  File "C:\Users\fx\PycharmProjects\webservice\venv\lib\site-packages\flask\app.py", line 1799, in dispatch_request
    return self.view_functions[rule.endpoint](**req.view_args)
  File "C:\Users\fx\PycharmProjects\new\app_newest.py", line 1071, in predict
    heatmap = create_plot( matrix, entities, relation, distribution_1[relation], entityX, entityY, last,operation[relation_chosen[-1]]["mX"], operation[relation_chosen[-1]]["mY"], operation[relation_chosen[-1]]["qX"], operation[relation_chosen[-1]]["qY"])
  File "C:\Users\fx\PycharmProjects\new\app_newest.py", line 365, in create_plot
    dendro = ff.create_dendrogram(temp_1, orientation='bottom')
  File "C:\Users\fx\PycharmProjects\webservice\venv\lib\site-packages\plotly\figure_factory\_dendrogram.py", line 91, in create_dendrogram
    hovertext=hovertext, color_threshold=color_threshold)
  File "C:\Users\fx\PycharmProjects\webservice\venv\lib\site-packages\plotly\figure_factory\_dendrogram.py", line 132, in __init__
    color_threshold)
  File "C:\Users\fx\PycharmProjects\webservice\venv\lib\site-packages\plotly\figure_factory\_dendrogram.py", line 276, in get_dendrogram_traces
    Z = linkagefun(d)
  File "C:\Users\fx\PycharmProjects\webservice\venv\lib\site-packages\plotly\figure_factory\_dendrogram.py", line 19, in <lambda>
    linkagefun=lambda x: sch.linkage(x, 'complete'),
  File "C:\Users\fx\PycharmProjects\webservice\venv\lib\site-packages\scipy\cluster\hierarchy.py", line 1064, in linkage
    n = int(distance.num_obs_y(y))
  File "C:\Users\fx\PycharmProjects\webservice\venv\lib\site-packages\scipy\spatial\distance.py", line 2403, in num_obs_y
    raise ValueError("The number of observations cannot be determined on "
ValueError: The number of observations cannot be determined on an empty distance matrix.
[2019-09-02 14:05:32,529][app_newest.py:1068][DEBUG]- AUC_ROC: 0.993322 ; AUC_PR: 0.971846 
[2019-09-02 14:05:32,530][app.py:1761][ERROR]- Exception on /predict [POST]
Traceback (most recent call last):
  File "C:\Users\fx\PycharmProjects\webservice\venv\lib\site-packages\flask\app.py", line 2292, in wsgi_app
    response = self.full_dispatch_request()
  File "C:\Users\fx\PycharmProjects\webservice\venv\lib\site-packages\flask\app.py", line 1815, in full_dispatch_request
    rv = self.handle_user_exception(e)
  File "C:\Users\fx\PycharmProjects\webservice\venv\lib\site-packages\flask\app.py", line 1718, in handle_user_exception
    reraise(exc_type, exc_value, tb)
  File "C:\Users\fx\PycharmProjects\webservice\venv\lib\site-packages\flask\_compat.py", line 35, in reraise
    raise value
  File "C:\Users\fx\PycharmProjects\webservice\venv\lib\site-packages\flask\app.py", line 1813, in full_dispatch_request
    rv = self.dispatch_request()
  File "C:\Users\fx\PycharmProjects\webservice\venv\lib\site-packages\flask\app.py", line 1799, in dispatch_request
    return self.view_functions[rule.endpoint](**req.view_args)
  File "C:\Users\fx\PycharmProjects\new\app_newest.py", line 1071, in predict
    heatmap = create_plot( matrix, entities, relation, distribution_1[relation], entityX, entityY, last,operation[relation_chosen[-1]]["mX"], operation[relation_chosen[-1]]["mY"], operation[relation_chosen[-1]]["qX"], operation[relation_chosen[-1]]["qY"])
  File "C:\Users\fx\PycharmProjects\new\app_newest.py", line 365, in create_plot
    dendro = ff.create_dendrogram(temp_1, orientation='bottom')
  File "C:\Users\fx\PycharmProjects\webservice\venv\lib\site-packages\plotly\figure_factory\_dendrogram.py", line 91, in create_dendrogram
    hovertext=hovertext, color_threshold=color_threshold)
  File "C:\Users\fx\PycharmProjects\webservice\venv\lib\site-packages\plotly\figure_factory\_dendrogram.py", line 132, in __init__
    color_threshold)
  File "C:\Users\fx\PycharmProjects\webservice\venv\lib\site-packages\plotly\figure_factory\_dendrogram.py", line 276, in get_dendrogram_traces
    Z = linkagefun(d)
  File "C:\Users\fx\PycharmProjects\webservice\venv\lib\site-packages\plotly\figure_factory\_dendrogram.py", line 19, in <lambda>
    linkagefun=lambda x: sch.linkage(x, 'complete'),
  File "C:\Users\fx\PycharmProjects\webservice\venv\lib\site-packages\scipy\cluster\hierarchy.py", line 1064, in linkage
    n = int(distance.num_obs_y(y))
  File "C:\Users\fx\PycharmProjects\webservice\venv\lib\site-packages\scipy\spatial\distance.py", line 2403, in num_obs_y
    raise ValueError("The number of observations cannot be determined on "
ValueError: The number of observations cannot be determined on an empty distance matrix.
[2019-09-02 14:05:53,811][app_newest.py:1068][DEBUG]- AUC_ROC: 0.993322 ; AUC_PR: 0.971846 
[2019-09-02 14:05:54,462][app_newest.py:1068][DEBUG]- AUC_ROC: 0.993322 ; AUC_PR: 0.971846 
[2019-09-02 15:18:49,548][app_umls_no_innercluster.py:1047][DEBUG]- AUC_ROC: 0.984368 ; AUC_PR: 0.814418 
[2019-09-02 15:18:57,670][app_umls_no_innercluster.py:1175][DEBUG]- AUC_ROC: 0.984368 ; AUC_PR: 0.814418 
[2019-09-02 15:25:38,123][app_umls_no_innercluster.py:1047][DEBUG]- AUC_ROC: 0.984368 ; AUC_PR: 0.814418 
[2019-09-02 15:26:38,625][app_umls_no_innercluster.py:1047][DEBUG]- AUC_ROC: 0.984368 ; AUC_PR: 0.814418 
[2019-09-02 15:27:33,092][app_umls_no_innercluster.py:1047][DEBUG]- AUC_ROC: 0.984368 ; AUC_PR: 0.814418 
[2019-09-02 15:28:03,969][app_umls_no_innercluster.py:1175][DEBUG]- AUC_ROC: 0.984368 ; AUC_PR: 0.814418 
[2019-09-03 14:49:49,907][app_umls_no_innercluster.py:1047][DEBUG]- AUC_ROC: 0.984368 ; AUC_PR: 0.814418 
[2019-09-03 14:50:09,216][app_umls_no_innercluster.py:1175][DEBUG]- AUC_ROC: 0.984368 ; AUC_PR: 0.814418 
[2019-09-03 14:50:34,825][app_umls_no_innercluster.py:1175][DEBUG]- AUC_ROC: 0.984368 ; AUC_PR: 0.814418 
[2019-09-03 14:50:38,121][app_umls_no_innercluster.py:1175][DEBUG]- AUC_ROC: 0.984368 ; AUC_PR: 0.814418 
[2019-09-03 14:50:46,428][app_umls_no_innercluster.py:1175][DEBUG]- AUC_ROC: 0.984368 ; AUC_PR: 0.814418 
[2019-09-03 14:51:09,509][app_umls_no_innercluster.py:1175][DEBUG]- AUC_ROC: 0.984368 ; AUC_PR: 0.814418 
[2019-09-03 14:57:45,907][app_newest.py:1068][DEBUG]- AUC_ROC: 0.993322 ; AUC_PR: 0.971846 
[2019-09-03 14:57:45,908][app.py:1761][ERROR]- Exception on /predict [POST]
Traceback (most recent call last):
  File "C:\Users\fx\PycharmProjects\webservice\venv\lib\site-packages\flask\app.py", line 2292, in wsgi_app
    response = self.full_dispatch_request()
  File "C:\Users\fx\PycharmProjects\webservice\venv\lib\site-packages\flask\app.py", line 1815, in full_dispatch_request
    rv = self.handle_user_exception(e)
  File "C:\Users\fx\PycharmProjects\webservice\venv\lib\site-packages\flask\app.py", line 1718, in handle_user_exception
    reraise(exc_type, exc_value, tb)
  File "C:\Users\fx\PycharmProjects\webservice\venv\lib\site-packages\flask\_compat.py", line 35, in reraise
    raise value
  File "C:\Users\fx\PycharmProjects\webservice\venv\lib\site-packages\flask\app.py", line 1813, in full_dispatch_request
    rv = self.dispatch_request()
  File "C:\Users\fx\PycharmProjects\webservice\venv\lib\site-packages\flask\app.py", line 1799, in dispatch_request
    return self.view_functions[rule.endpoint](**req.view_args)
  File "C:\Users\fx\PycharmProjects\new\app_newest.py", line 1071, in predict
    heatmap = create_plot( matrix, entities, relation, distribution_1[relation], entityX, entityY, last,operation[relation_chosen[-1]]["mX"], operation[relation_chosen[-1]]["mY"], operation[relation_chosen[-1]]["qX"], operation[relation_chosen[-1]]["qY"])
  File "C:\Users\fx\PycharmProjects\new\app_newest.py", line 365, in create_plot
    dendro = ff.create_dendrogram(temp_1, orientation='bottom')
  File "C:\Users\fx\PycharmProjects\webservice\venv\lib\site-packages\plotly\figure_factory\_dendrogram.py", line 91, in create_dendrogram
    hovertext=hovertext, color_threshold=color_threshold)
  File "C:\Users\fx\PycharmProjects\webservice\venv\lib\site-packages\plotly\figure_factory\_dendrogram.py", line 132, in __init__
    color_threshold)
  File "C:\Users\fx\PycharmProjects\webservice\venv\lib\site-packages\plotly\figure_factory\_dendrogram.py", line 276, in get_dendrogram_traces
    Z = linkagefun(d)
  File "C:\Users\fx\PycharmProjects\webservice\venv\lib\site-packages\plotly\figure_factory\_dendrogram.py", line 19, in <lambda>
    linkagefun=lambda x: sch.linkage(x, 'complete'),
  File "C:\Users\fx\PycharmProjects\webservice\venv\lib\site-packages\scipy\cluster\hierarchy.py", line 1064, in linkage
    n = int(distance.num_obs_y(y))
  File "C:\Users\fx\PycharmProjects\webservice\venv\lib\site-packages\scipy\spatial\distance.py", line 2403, in num_obs_y
    raise ValueError("The number of observations cannot be determined on "
ValueError: The number of observations cannot be determined on an empty distance matrix.
[2019-09-03 14:58:07,828][app_newest.py:1068][DEBUG]- AUC_ROC: 0.993322 ; AUC_PR: 0.971846 
[2019-09-03 14:58:07,828][app.py:1761][ERROR]- Exception on /predict [POST]
Traceback (most recent call last):
  File "C:\Users\fx\PycharmProjects\webservice\venv\lib\site-packages\flask\app.py", line 2292, in wsgi_app
    response = self.full_dispatch_request()
  File "C:\Users\fx\PycharmProjects\webservice\venv\lib\site-packages\flask\app.py", line 1815, in full_dispatch_request
    rv = self.handle_user_exception(e)
  File "C:\Users\fx\PycharmProjects\webservice\venv\lib\site-packages\flask\app.py", line 1718, in handle_user_exception
    reraise(exc_type, exc_value, tb)
  File "C:\Users\fx\PycharmProjects\webservice\venv\lib\site-packages\flask\_compat.py", line 35, in reraise
    raise value
  File "C:\Users\fx\PycharmProjects\webservice\venv\lib\site-packages\flask\app.py", line 1813, in full_dispatch_request
    rv = self.dispatch_request()
  File "C:\Users\fx\PycharmProjects\webservice\venv\lib\site-packages\flask\app.py", line 1799, in dispatch_request
    return self.view_functions[rule.endpoint](**req.view_args)
  File "C:\Users\fx\PycharmProjects\new\app_newest.py", line 1071, in predict
    heatmap = create_plot( matrix, entities, relation, distribution_1[relation], entityX, entityY, last,operation[relation_chosen[-1]]["mX"], operation[relation_chosen[-1]]["mY"], operation[relation_chosen[-1]]["qX"], operation[relation_chosen[-1]]["qY"])
  File "C:\Users\fx\PycharmProjects\new\app_newest.py", line 365, in create_plot
    dendro = ff.create_dendrogram(temp_1, orientation='bottom')
  File "C:\Users\fx\PycharmProjects\webservice\venv\lib\site-packages\plotly\figure_factory\_dendrogram.py", line 91, in create_dendrogram
    hovertext=hovertext, color_threshold=color_threshold)
  File "C:\Users\fx\PycharmProjects\webservice\venv\lib\site-packages\plotly\figure_factory\_dendrogram.py", line 132, in __init__
    color_threshold)
  File "C:\Users\fx\PycharmProjects\webservice\venv\lib\site-packages\plotly\figure_factory\_dendrogram.py", line 276, in get_dendrogram_traces
    Z = linkagefun(d)
  File "C:\Users\fx\PycharmProjects\webservice\venv\lib\site-packages\plotly\figure_factory\_dendrogram.py", line 19, in <lambda>
    linkagefun=lambda x: sch.linkage(x, 'complete'),
  File "C:\Users\fx\PycharmProjects\webservice\venv\lib\site-packages\scipy\cluster\hierarchy.py", line 1064, in linkage
    n = int(distance.num_obs_y(y))
  File "C:\Users\fx\PycharmProjects\webservice\venv\lib\site-packages\scipy\spatial\distance.py", line 2403, in num_obs_y
    raise ValueError("The number of observations cannot be determined on "
ValueError: The number of observations cannot be determined on an empty distance matrix.
[2019-09-03 14:59:02,011][app_newest.py:1068][DEBUG]- AUC_ROC: 0.993322 ; AUC_PR: 0.971846 
[2019-09-03 14:59:02,011][app.py:1761][ERROR]- Exception on /predict [POST]
Traceback (most recent call last):
  File "C:\Users\fx\PycharmProjects\webservice\venv\lib\site-packages\flask\app.py", line 2292, in wsgi_app
    response = self.full_dispatch_request()
  File "C:\Users\fx\PycharmProjects\webservice\venv\lib\site-packages\flask\app.py", line 1815, in full_dispatch_request
    rv = self.handle_user_exception(e)
  File "C:\Users\fx\PycharmProjects\webservice\venv\lib\site-packages\flask\app.py", line 1718, in handle_user_exception
    reraise(exc_type, exc_value, tb)
  File "C:\Users\fx\PycharmProjects\webservice\venv\lib\site-packages\flask\_compat.py", line 35, in reraise
    raise value
  File "C:\Users\fx\PycharmProjects\webservice\venv\lib\site-packages\flask\app.py", line 1813, in full_dispatch_request
    rv = self.dispatch_request()
  File "C:\Users\fx\PycharmProjects\webservice\venv\lib\site-packages\flask\app.py", line 1799, in dispatch_request
    return self.view_functions[rule.endpoint](**req.view_args)
  File "C:\Users\fx\PycharmProjects\new\app_newest.py", line 1071, in predict
    heatmap = create_plot( matrix, entities, relation, distribution_1[relation], entityX, entityY, last,operation[relation_chosen[-1]]["mX"], operation[relation_chosen[-1]]["mY"], operation[relation_chosen[-1]]["qX"], operation[relation_chosen[-1]]["qY"])
  File "C:\Users\fx\PycharmProjects\new\app_newest.py", line 411, in create_plot
    new_row.append(test[j, i])
NameError: name 'test' is not defined
[2019-09-03 14:59:41,551][app_newest.py:1068][DEBUG]- AUC_ROC: 0.993322 ; AUC_PR: 0.971846 
[2019-09-03 14:59:49,492][app_newest.py:1196][DEBUG]- AUC_ROC: 0.993322 ; AUC_PR: 0.971846 
[2019-09-03 14:59:52,233][app_newest.py:1196][DEBUG]- AUC_ROC: 0.993322 ; AUC_PR: 0.971846 
[2019-09-03 14:59:56,295][app_newest.py:1196][DEBUG]- AUC_ROC: 0.993322 ; AUC_PR: 0.971846 
[2019-09-03 15:00:08,786][app_newest.py:1196][DEBUG]- AUC_ROC: 0.993322 ; AUC_PR: 0.971846 
[2019-09-03 15:00:10,503][app_newest.py:1196][DEBUG]- AUC_ROC: 0.993322 ; AUC_PR: 0.971846 
[2019-09-03 15:00:12,838][app_newest.py:1196][DEBUG]- AUC_ROC: 0.993322 ; AUC_PR: 0.971846 
[2019-09-03 15:00:14,560][app_newest.py:1196][DEBUG]- AUC_ROC: 0.993322 ; AUC_PR: 0.971846 
[2019-09-03 15:00:15,826][app_newest.py:1196][DEBUG]- AUC_ROC: 0.993322 ; AUC_PR: 0.971846 
[2019-09-03 15:00:17,272][app_newest.py:1196][DEBUG]- AUC_ROC: 0.993322 ; AUC_PR: 0.971846 
[2019-09-03 15:00:47,184][app_newest.py:1196][DEBUG]- AUC_ROC: 0.993322 ; AUC_PR: 0.971846 
[2019-09-03 15:00:52,214][app_newest.py:1196][DEBUG]- AUC_ROC: 0.993322 ; AUC_PR: 0.971846 
[2019-09-03 15:01:12,302][app_newest.py:1196][DEBUG]- AUC_ROC: 0.993322 ; AUC_PR: 0.971846 
[2019-09-03 15:01:14,599][app_newest.py:1196][DEBUG]- AUC_ROC: 0.993322 ; AUC_PR: 0.971846 
[2019-09-03 15:01:25,375][app_newest.py:1196][DEBUG]- AUC_ROC: 0.993322 ; AUC_PR: 0.971846 
[2019-09-03 15:01:32,729][app_newest.py:1196][DEBUG]- AUC_ROC: 0.993322 ; AUC_PR: 0.971846 
[2019-09-03 15:01:42,008][app_newest.py:1196][DEBUG]- AUC_ROC: 0.993322 ; AUC_PR: 0.971846 
[2019-09-03 15:01:51,701][app_newest.py:1196][DEBUG]- AUC_ROC: 0.993322 ; AUC_PR: 0.971846 
[2019-09-03 15:02:20,856][app_newest.py:1196][DEBUG]- AUC_ROC: 0.993322 ; AUC_PR: 0.971846 
[2019-09-03 15:02:31,513][app_newest.py:1196][DEBUG]- AUC_ROC: 0.993322 ; AUC_PR: 0.971846 
[2019-09-03 15:02:33,960][app_newest.py:1196][DEBUG]- AUC_ROC: 0.993322 ; AUC_PR: 0.971846 
[2019-09-03 15:02:42,026][app_newest.py:1196][DEBUG]- AUC_ROC: 0.993322 ; AUC_PR: 0.971846 
[2019-09-03 15:02:48,552][app_newest.py:1196][DEBUG]- AUC_ROC: 0.993322 ; AUC_PR: 0.971846 
[2019-09-03 15:02:49,816][app_newest.py:1196][DEBUG]- AUC_ROC: 0.993322 ; AUC_PR: 0.971846 
[2019-09-03 15:02:52,482][app_newest.py:1196][DEBUG]- AUC_ROC: 0.993322 ; AUC_PR: 0.971846 
[2019-09-03 15:02:54,097][app_newest.py:1196][DEBUG]- AUC_ROC: 0.993322 ; AUC_PR: 0.971846 
[2019-09-03 15:02:55,744][app_newest.py:1196][DEBUG]- AUC_ROC: 0.993322 ; AUC_PR: 0.971846 
[2019-09-03 15:02:57,512][app_newest.py:1196][DEBUG]- AUC_ROC: 0.993322 ; AUC_PR: 0.971846 
[2019-09-03 15:02:58,682][app_newest.py:1196][DEBUG]- AUC_ROC: 0.993322 ; AUC_PR: 0.971846 
[2019-09-03 15:03:07,780][app_newest.py:1196][DEBUG]- AUC_ROC: 0.993322 ; AUC_PR: 0.971846 
[2019-09-03 15:03:10,058][app_newest.py:1196][DEBUG]- AUC_ROC: 0.993322 ; AUC_PR: 0.971846 
[2019-09-03 15:03:38,671][app_newest.py:1196][DEBUG]- AUC_ROC: 0.993322 ; AUC_PR: 0.971846 
[2019-09-03 15:03:39,764][app_newest.py:1196][DEBUG]- AUC_ROC: 0.993322 ; AUC_PR: 0.971846 
[2019-09-03 15:03:42,165][app_newest.py:1196][DEBUG]- AUC_ROC: 0.993322 ; AUC_PR: 0.971846 
[2019-09-03 15:03:43,501][app_newest.py:1196][DEBUG]- AUC_ROC: 0.993322 ; AUC_PR: 0.971846 
[2019-09-03 15:04:55,932][app_newest.py:1196][DEBUG]- AUC_ROC: 0.993322 ; AUC_PR: 0.971846 
[2019-09-03 15:05:14,748][app_newest.py:1196][DEBUG]- AUC_ROC: 0.993322 ; AUC_PR: 0.971846 
[2019-09-03 15:05:19,196][app_newest.py:1196][DEBUG]- AUC_ROC: 0.993322 ; AUC_PR: 0.971846 
[2019-09-03 15:05:20,680][app_newest.py:1196][DEBUG]- AUC_ROC: 0.993322 ; AUC_PR: 0.971846 
[2019-09-03 15:05:21,931][app_newest.py:1196][DEBUG]- AUC_ROC: 0.993322 ; AUC_PR: 0.971846 
[2019-09-03 15:05:23,153][app_newest.py:1196][DEBUG]- AUC_ROC: 0.993322 ; AUC_PR: 0.971846 
[2019-09-03 15:05:27,126][app_newest.py:1196][DEBUG]- AUC_ROC: 0.993322 ; AUC_PR: 0.971846 
[2019-09-03 15:44:44,843][app_nothing.py:1062][DEBUG]- AUC_ROC: 0.993322 ; AUC_PR: 0.971846 
[2019-09-03 15:45:27,674][app_nothing.py:1062][DEBUG]- AUC_ROC: 0.993322 ; AUC_PR: 0.971846 
[2019-09-03 15:46:24,712][app_nothing.py:1062][DEBUG]- AUC_ROC: 0.993322 ; AUC_PR: 0.971846 
[2019-09-04 09:20:13,000][app_rescal_test.py:1068][DEBUG]- AUC_ROC: 0.993322 ; AUC_PR: 0.971846 
[2019-09-04 09:48:36,786][app_newest.py:1068][DEBUG]- AUC_ROC: 0.993322 ; AUC_PR: 0.971846 
[2019-09-04 09:51:50,789][app_newest.py:1068][DEBUG]- AUC_ROC: 0.993322 ; AUC_PR: 0.971846 
[2019-09-04 11:28:55,205][app_newest.py:1068][DEBUG]- AUC_ROC: 0.993322 ; AUC_PR: 0.971846 
[2019-09-04 11:29:03,034][app_newest.py:1196][DEBUG]- AUC_ROC: 0.993322 ; AUC_PR: 0.971846 
[2019-09-04 11:29:04,966][app_newest.py:1196][DEBUG]- AUC_ROC: 0.993322 ; AUC_PR: 0.971846 
[2019-09-04 11:29:06,905][app_newest.py:1196][DEBUG]- AUC_ROC: 0.993322 ; AUC_PR: 0.971846 
[2019-09-04 11:29:08,781][app_newest.py:1196][DEBUG]- AUC_ROC: 0.993322 ; AUC_PR: 0.971846 
[2019-09-04 16:33:10,457][app_newest.py:1068][DEBUG]- AUC_ROC: 0.993322 ; AUC_PR: 0.971846 
[2019-09-04 16:35:11,567][app.py:1039][DEBUG]- AUC_ROC: 0.992668 ; AUC_PR: 0.969914 
[2019-09-04 16:35:11,657][app.py:1761][ERROR]- Exception on /predict [POST]
Traceback (most recent call last):
  File "C:\Users\fx\PycharmProjects\webservice\venv\lib\site-packages\flask\app.py", line 2292, in wsgi_app
    response = self.full_dispatch_request()
  File "C:\Users\fx\PycharmProjects\webservice\venv\lib\site-packages\flask\app.py", line 1815, in full_dispatch_request
    rv = self.handle_user_exception(e)
  File "C:\Users\fx\PycharmProjects\webservice\venv\lib\site-packages\flask\app.py", line 1718, in handle_user_exception
    reraise(exc_type, exc_value, tb)
  File "C:\Users\fx\PycharmProjects\webservice\venv\lib\site-packages\flask\_compat.py", line 35, in reraise
    raise value
  File "C:\Users\fx\PycharmProjects\webservice\venv\lib\site-packages\flask\app.py", line 1813, in full_dispatch_request
    rv = self.dispatch_request()
  File "C:\Users\fx\PycharmProjects\webservice\venv\lib\site-packages\flask\app.py", line 1799, in dispatch_request
    return self.view_functions[rule.endpoint](**req.view_args)
  File "C:\Users\fx\PycharmProjects\new\app.py", line 1042, in predict
    heatmap,entities_x, entities_y = create_plot( matrix, entities, relation, distribution_1[relation], entityX, entityY, last,operation[relation_chosen[-1]]["mX"], operation[relation_chosen[-1]]["mY"], operation[relation_chosen[-1]]["qX"], operation[relation_chosen[-1]]["qY"])
  File "C:\Users\fx\PycharmProjects\new\app.py", line 373, in create_plot
    dendro = ff.create_dendrogram(temp_1, orientation='bottom')
  File "C:\Users\fx\PycharmProjects\webservice\venv\lib\site-packages\plotly\figure_factory\_dendrogram.py", line 91, in create_dendrogram
    hovertext=hovertext, color_threshold=color_threshold)
  File "C:\Users\fx\PycharmProjects\webservice\venv\lib\site-packages\plotly\figure_factory\_dendrogram.py", line 132, in __init__
    color_threshold)
  File "C:\Users\fx\PycharmProjects\webservice\venv\lib\site-packages\plotly\figure_factory\_dendrogram.py", line 276, in get_dendrogram_traces
    Z = linkagefun(d)
  File "C:\Users\fx\PycharmProjects\webservice\venv\lib\site-packages\plotly\figure_factory\_dendrogram.py", line 19, in <lambda>
    linkagefun=lambda x: sch.linkage(x, 'complete'),
  File "C:\Users\fx\PycharmProjects\webservice\venv\lib\site-packages\scipy\cluster\hierarchy.py", line 1064, in linkage
    n = int(distance.num_obs_y(y))
  File "C:\Users\fx\PycharmProjects\webservice\venv\lib\site-packages\scipy\spatial\distance.py", line 2403, in num_obs_y
    raise ValueError("The number of observations cannot be determined on "
ValueError: The number of observations cannot be determined on an empty distance matrix.
[2019-09-04 16:35:47,749][app.py:1039][DEBUG]- AUC_ROC: 0.992407 ; AUC_PR: 0.970894 
[2019-09-04 16:36:37,158][app.py:1039][DEBUG]- AUC_ROC: 0.991813 ; AUC_PR: 0.968873 
[2019-09-04 16:36:37,289][app.py:1761][ERROR]- Exception on /predict [POST]
Traceback (most recent call last):
  File "C:\Users\fx\PycharmProjects\webservice\venv\lib\site-packages\flask\app.py", line 2292, in wsgi_app
    response = self.full_dispatch_request()
  File "C:\Users\fx\PycharmProjects\webservice\venv\lib\site-packages\flask\app.py", line 1815, in full_dispatch_request
    rv = self.handle_user_exception(e)
  File "C:\Users\fx\PycharmProjects\webservice\venv\lib\site-packages\flask\app.py", line 1718, in handle_user_exception
    reraise(exc_type, exc_value, tb)
  File "C:\Users\fx\PycharmProjects\webservice\venv\lib\site-packages\flask\_compat.py", line 35, in reraise
    raise value
  File "C:\Users\fx\PycharmProjects\webservice\venv\lib\site-packages\flask\app.py", line 1813, in full_dispatch_request
    rv = self.dispatch_request()
  File "C:\Users\fx\PycharmProjects\webservice\venv\lib\site-packages\flask\app.py", line 1799, in dispatch_request
    return self.view_functions[rule.endpoint](**req.view_args)
  File "C:\Users\fx\PycharmProjects\new\app.py", line 1042, in predict
    heatmap,entities_x, entities_y = create_plot( matrix, entities, relation, distribution_1[relation], entityX, entityY, last,operation[relation_chosen[-1]]["mX"], operation[relation_chosen[-1]]["mY"], operation[relation_chosen[-1]]["qX"], operation[relation_chosen[-1]]["qY"])
  File "C:\Users\fx\PycharmProjects\new\app.py", line 373, in create_plot
    dendro = ff.create_dendrogram(temp_1, orientation='bottom')
  File "C:\Users\fx\PycharmProjects\webservice\venv\lib\site-packages\plotly\figure_factory\_dendrogram.py", line 91, in create_dendrogram
    hovertext=hovertext, color_threshold=color_threshold)
  File "C:\Users\fx\PycharmProjects\webservice\venv\lib\site-packages\plotly\figure_factory\_dendrogram.py", line 132, in __init__
    color_threshold)
  File "C:\Users\fx\PycharmProjects\webservice\venv\lib\site-packages\plotly\figure_factory\_dendrogram.py", line 276, in get_dendrogram_traces
    Z = linkagefun(d)
  File "C:\Users\fx\PycharmProjects\webservice\venv\lib\site-packages\plotly\figure_factory\_dendrogram.py", line 19, in <lambda>
    linkagefun=lambda x: sch.linkage(x, 'complete'),
  File "C:\Users\fx\PycharmProjects\webservice\venv\lib\site-packages\scipy\cluster\hierarchy.py", line 1064, in linkage
    n = int(distance.num_obs_y(y))
  File "C:\Users\fx\PycharmProjects\webservice\venv\lib\site-packages\scipy\spatial\distance.py", line 2403, in num_obs_y
    raise ValueError("The number of observations cannot be determined on "
ValueError: The number of observations cannot be determined on an empty distance matrix.
[2019-09-04 16:36:52,233][app.py:1039][DEBUG]- AUC_ROC: 0.992318 ; AUC_PR: 0.970387 
[2019-09-04 16:37:50,286][app_newest.py:1068][DEBUG]- AUC_ROC: 0.992318 ; AUC_PR: 0.970387 
[2019-09-04 16:47:13,604][app_newest.py:1068][DEBUG]- AUC_ROC: 0.992318 ; AUC_PR: 0.970387 
[2019-09-04 16:47:45,227][app_rescal_test.py:1068][DEBUG]- AUC_ROC: 0.992318 ; AUC_PR: 0.970387 
[2019-09-04 16:47:54,886][app_rescal_test.py:1196][DEBUG]- AUC_ROC: 0.992318 ; AUC_PR: 0.970387 
